[2022-12-16T14:24:34.619+0000] {taskinstance.py:1081} INFO - Dependencies not met for <TaskInstance: postgresoperator_demo.insert_data_task manual__2022-12-16T14:02:43.186476+00:00 [success]>, dependency 'Task Instance State' FAILED: Task is in the 'success' state.
[2022-12-16T14:24:34.649+0000] {local_task_job.py:98} INFO - Task is not able to be run
[2022-12-18T10:15:18.678+0000] {taskinstance.py:1087} INFO - Dependencies all met for <TaskInstance: postgresoperator_demo.insert_data_task manual__2022-12-16T14:02:43.186476+00:00 [queued]>
[2022-12-18T10:15:18.705+0000] {taskinstance.py:1087} INFO - Dependencies all met for <TaskInstance: postgresoperator_demo.insert_data_task manual__2022-12-16T14:02:43.186476+00:00 [queued]>
[2022-12-18T10:15:18.706+0000] {taskinstance.py:1283} INFO - 
--------------------------------------------------------------------------------
[2022-12-18T10:15:18.707+0000] {taskinstance.py:1284} INFO - Starting attempt 3 of 3
[2022-12-18T10:15:18.708+0000] {taskinstance.py:1285} INFO - 
--------------------------------------------------------------------------------
[2022-12-18T10:15:18.748+0000] {taskinstance.py:1304} INFO - Executing <Task(PostgresOperator): insert_data_task> on 2022-12-16 14:02:43.186476+00:00
[2022-12-18T10:15:18.761+0000] {standard_task_runner.py:55} INFO - Started process 353 to run task
[2022-12-18T10:15:18.782+0000] {standard_task_runner.py:82} INFO - Running: ['***', 'tasks', 'run', 'postgresoperator_demo', 'insert_data_task', 'manual__2022-12-16T14:02:43.186476+00:00', '--job-id', '81', '--raw', '--subdir', 'DAGS_FOLDER/my_new_dag.py', '--cfg-path', '/tmp/tmpeh1q4ieh']
[2022-12-18T10:15:18.784+0000] {standard_task_runner.py:83} INFO - Job 81: Subtask insert_data_task
[2022-12-18T10:15:19.415+0000] {task_command.py:389} INFO - Running <TaskInstance: postgresoperator_demo.insert_data_task manual__2022-12-16T14:02:43.186476+00:00 [running]> on host 1ca23c4c3c1c
[2022-12-18T10:15:42.610+0000] {base_job.py:232} ERROR - LocalTaskJob heartbeat got an exception
Traceback (most recent call last):
  File "/home/airflow/.local/lib/python3.7/site-packages/sqlalchemy/engine/base.py", line 3361, in _wrap_pool_connect
    return fn()
  File "/home/airflow/.local/lib/python3.7/site-packages/sqlalchemy/pool/base.py", line 325, in connect
    return _ConnectionFairy._checkout(self)
  File "/home/airflow/.local/lib/python3.7/site-packages/sqlalchemy/pool/base.py", line 888, in _checkout
    fairy = _ConnectionRecord.checkout(pool)
  File "/home/airflow/.local/lib/python3.7/site-packages/sqlalchemy/pool/base.py", line 491, in checkout
    rec = pool._do_get()
  File "/home/airflow/.local/lib/python3.7/site-packages/sqlalchemy/pool/impl.py", line 256, in _do_get
    return self._create_connection()
  File "/home/airflow/.local/lib/python3.7/site-packages/sqlalchemy/pool/base.py", line 271, in _create_connection
    return _ConnectionRecord(self)
  File "/home/airflow/.local/lib/python3.7/site-packages/sqlalchemy/pool/base.py", line 386, in __init__
    self.__connect()
  File "/home/airflow/.local/lib/python3.7/site-packages/sqlalchemy/pool/base.py", line 685, in __connect
    pool.logger.debug("Error on connect(): %s", e)
  File "/home/airflow/.local/lib/python3.7/site-packages/sqlalchemy/util/langhelpers.py", line 72, in __exit__
    with_traceback=exc_tb,
  File "/home/airflow/.local/lib/python3.7/site-packages/sqlalchemy/util/compat.py", line 210, in raise_
    raise exception
  File "/home/airflow/.local/lib/python3.7/site-packages/sqlalchemy/pool/base.py", line 680, in __connect
    self.dbapi_connection = connection = pool._invoke_creator(self)
  File "/home/airflow/.local/lib/python3.7/site-packages/sqlalchemy/engine/create.py", line 578, in connect
    return dialect.connect(*cargs, **cparams)
  File "/home/airflow/.local/lib/python3.7/site-packages/sqlalchemy/engine/default.py", line 598, in connect
    return self.dbapi.connect(*cargs, **cparams)
  File "/home/airflow/.local/lib/python3.7/site-packages/psycopg2/__init__.py", line 122, in connect
    conn = _connect(dsn, connection_factory=connection_factory, **kwasync)
psycopg2.OperationalError: could not translate host name "postgres" to address: Temporary failure in name resolution


The above exception was the direct cause of the following exception:

Traceback (most recent call last):
  File "/home/airflow/.local/lib/python3.7/site-packages/airflow/jobs/base_job.py", line 204, in heartbeat
    session.merge(self)
  File "/home/airflow/.local/lib/python3.7/site-packages/sqlalchemy/orm/session.py", line 3057, in merge
    _resolve_conflict_map=_resolve_conflict_map,
  File "/home/airflow/.local/lib/python3.7/site-packages/sqlalchemy/orm/session.py", line 3135, in _merge
    options=options,
  File "/home/airflow/.local/lib/python3.7/site-packages/sqlalchemy/orm/session.py", line 2856, in get
    execution_options=execution_options,
  File "/home/airflow/.local/lib/python3.7/site-packages/sqlalchemy/orm/session.py", line 2974, in _get_impl
    load_options=load_options,
  File "/home/airflow/.local/lib/python3.7/site-packages/sqlalchemy/orm/loading.py", line 534, in load_on_pk_identity
    bind_arguments=bind_arguments,
  File "/home/airflow/.local/lib/python3.7/site-packages/sqlalchemy/orm/session.py", line 1713, in execute
    conn = self._connection_for_bind(bind)
  File "/home/airflow/.local/lib/python3.7/site-packages/sqlalchemy/orm/session.py", line 1553, in _connection_for_bind
    engine, execution_options
  File "/home/airflow/.local/lib/python3.7/site-packages/sqlalchemy/orm/session.py", line 747, in _connection_for_bind
    conn = bind.connect()
  File "/home/airflow/.local/lib/python3.7/site-packages/sqlalchemy/engine/base.py", line 3315, in connect
    return self._connection_cls(self, close_with_result=close_with_result)
  File "/home/airflow/.local/lib/python3.7/site-packages/sqlalchemy/engine/base.py", line 96, in __init__
    else engine.raw_connection()
  File "/home/airflow/.local/lib/python3.7/site-packages/sqlalchemy/engine/base.py", line 3394, in raw_connection
    return self._wrap_pool_connect(self.pool.connect, _connection)
  File "/home/airflow/.local/lib/python3.7/site-packages/sqlalchemy/engine/base.py", line 3365, in _wrap_pool_connect
    e, dialect, self
  File "/home/airflow/.local/lib/python3.7/site-packages/sqlalchemy/engine/base.py", line 2199, in _handle_dbapi_exception_noconnection
    sqlalchemy_exception, with_traceback=exc_info[2], from_=e
  File "/home/airflow/.local/lib/python3.7/site-packages/sqlalchemy/util/compat.py", line 210, in raise_
    raise exception
  File "/home/airflow/.local/lib/python3.7/site-packages/sqlalchemy/engine/base.py", line 3361, in _wrap_pool_connect
    return fn()
  File "/home/airflow/.local/lib/python3.7/site-packages/sqlalchemy/pool/base.py", line 325, in connect
    return _ConnectionFairy._checkout(self)
  File "/home/airflow/.local/lib/python3.7/site-packages/sqlalchemy/pool/base.py", line 888, in _checkout
    fairy = _ConnectionRecord.checkout(pool)
  File "/home/airflow/.local/lib/python3.7/site-packages/sqlalchemy/pool/base.py", line 491, in checkout
    rec = pool._do_get()
  File "/home/airflow/.local/lib/python3.7/site-packages/sqlalchemy/pool/impl.py", line 256, in _do_get
    return self._create_connection()
  File "/home/airflow/.local/lib/python3.7/site-packages/sqlalchemy/pool/base.py", line 271, in _create_connection
    return _ConnectionRecord(self)
  File "/home/airflow/.local/lib/python3.7/site-packages/sqlalchemy/pool/base.py", line 386, in __init__
    self.__connect()
  File "/home/airflow/.local/lib/python3.7/site-packages/sqlalchemy/pool/base.py", line 685, in __connect
    pool.logger.debug("Error on connect(): %s", e)
  File "/home/airflow/.local/lib/python3.7/site-packages/sqlalchemy/util/langhelpers.py", line 72, in __exit__
    with_traceback=exc_tb,
  File "/home/airflow/.local/lib/python3.7/site-packages/sqlalchemy/util/compat.py", line 210, in raise_
    raise exception
  File "/home/airflow/.local/lib/python3.7/site-packages/sqlalchemy/pool/base.py", line 680, in __connect
    self.dbapi_connection = connection = pool._invoke_creator(self)
  File "/home/airflow/.local/lib/python3.7/site-packages/sqlalchemy/engine/create.py", line 578, in connect
    return dialect.connect(*cargs, **cparams)
  File "/home/airflow/.local/lib/python3.7/site-packages/sqlalchemy/engine/default.py", line 598, in connect
    return self.dbapi.connect(*cargs, **cparams)
  File "/home/airflow/.local/lib/python3.7/site-packages/psycopg2/__init__.py", line 122, in connect
    conn = _connect(dsn, connection_factory=connection_factory, **kwasync)
sqlalchemy.exc.OperationalError: (psycopg2.OperationalError) could not translate host name "postgres" to address: Temporary failure in name resolution

(Background on this error at: https://sqlalche.me/e/14/e3q8)
[2022-12-18T10:16:43.504+0000] {taskinstance.py:1513} INFO - Exporting the following env vars:
AIRFLOW_CTX_DAG_OWNER=***
AIRFLOW_CTX_DAG_ID=postgresoperator_demo
AIRFLOW_CTX_TASK_ID=insert_data_task
AIRFLOW_CTX_EXECUTION_DATE=2022-12-16T14:02:43.186476+00:00
AIRFLOW_CTX_TRY_NUMBER=3
AIRFLOW_CTX_DAG_RUN_ID=manual__2022-12-16T14:02:43.186476+00:00
[2022-12-18T10:16:43.510+0000] {sql.py:253} INFO - Executing: 
#                     COPY traffic_data(id, track_id, type, traveled_d, avg_speed, lat, lon, speed, lon_acc, lat_acc, time)
#                     FROM './traffic_data2.csv'
#                     DELIMITER ','
#                     CSV HEADER;
#               
[2022-12-18T10:16:43.826+0000] {base.py:73} INFO - Using connection ID 'postgres_localhost' for task execution.
[2022-12-18T10:17:07.504+0000] {base.py:73} INFO - Using connection ID 'postgres_localhost' for task execution.
[2022-12-18T10:17:07.518+0000] {sql.py:364} INFO - Running statement: 
#                     COPY traffic_data(id, track_id, type, traveled_d, avg_speed, lat, lon, speed, lon_acc, lat_acc, time)
#                     FROM './traffic_data2.csv'
#                     DELIMITER ','
#                     CSV HEADER;
#               , parameters: None
[2022-12-18T10:17:07.527+0000] {taskinstance.py:1772} ERROR - Task failed with exception
Traceback (most recent call last):
  File "/home/airflow/.local/lib/python3.7/site-packages/airflow/providers/common/sql/operators/sql.py", line 261, in execute
    return_last=self.return_last,
  File "/home/airflow/.local/lib/python3.7/site-packages/airflow/providers/common/sql/hooks/sql.py", line 338, in run
    self._run_command(cur, sql_statement, parameters)
  File "/home/airflow/.local/lib/python3.7/site-packages/airflow/providers/common/sql/hooks/sql.py", line 369, in _run_command
    cur.execute(sql_statement)
psycopg2.errors.SyntaxError: syntax error at or near "#"
LINE 2: #                     COPY traffic_data(id, track_id, type, ...
        ^

[2022-12-18T10:17:07.558+0000] {taskinstance.py:1327} INFO - Marking task as FAILED. dag_id=postgresoperator_demo, task_id=insert_data_task, execution_date=20221216T140243, start_date=20221218T101518, end_date=20221218T101707
[2022-12-18T10:17:07.610+0000] {standard_task_runner.py:105} ERROR - Failed to execute job 81 for task insert_data_task (syntax error at or near "#"
LINE 2: #                     COPY traffic_data(id, track_id, type, ...
        ^
; 353)
[2022-12-18T10:17:07.658+0000] {local_task_job.py:159} INFO - Task exited with return code 1
[2022-12-18T10:17:07.752+0000] {taskinstance.py:2582} INFO - 0 downstream tasks scheduled from follow-on schedule check
