[2022-12-18T01:36:38.120+0000] {taskinstance.py:1087} INFO - Dependencies all met for <TaskInstance: postgres_with_airflow.create_table_task manual__2022-12-18T00:23:41.975796+00:00 [queued]>
[2022-12-18T01:36:39.731+0000] {taskinstance.py:1087} INFO - Dependencies all met for <TaskInstance: postgres_with_airflow.create_table_task manual__2022-12-18T00:23:41.975796+00:00 [queued]>
[2022-12-18T01:36:39.751+0000] {taskinstance.py:1283} INFO - 
--------------------------------------------------------------------------------
[2022-12-18T01:36:40.056+0000] {taskinstance.py:1284} INFO - Starting attempt 5 of 5
[2022-12-18T01:36:40.082+0000] {taskinstance.py:1285} INFO - 
--------------------------------------------------------------------------------
[2022-12-18T01:36:50.800+0000] {taskinstance.py:1304} INFO - Executing <Task(PostgresOperator): create_table_task> on 2022-12-18 00:23:41.975796+00:00
[2022-12-18T01:36:51.114+0000] {standard_task_runner.py:82} INFO - Running: ['***', 'tasks', 'run', 'postgres_with_***', 'create_table_task', 'manual__2022-12-18T00:23:41.975796+00:00', '--job-id', '64', '--raw', '--subdir', 'DAGS_FOLDER/dag_with_postgres.py', '--cfg-path', '/tmp/tmp_pbfe_nq']
[2022-12-18T01:36:51.001+0000] {standard_task_runner.py:55} INFO - Started process 1161 to run task
[2022-12-18T01:36:51.159+0000] {standard_task_runner.py:83} INFO - Job 64: Subtask create_table_task
[2022-12-18T01:36:55.613+0000] {task_command.py:389} INFO - Running <TaskInstance: postgres_with_airflow.create_table_task manual__2022-12-18T00:23:41.975796+00:00 [running]> on host f376bb2680d1
[2022-12-18T01:38:10.948+0000] {taskinstance.py:1513} INFO - Exporting the following env vars:
AIRFLOW_CTX_DAG_OWNER=***
AIRFLOW_CTX_DAG_ID=postgres_with_***
AIRFLOW_CTX_TASK_ID=create_table_task
AIRFLOW_CTX_EXECUTION_DATE=2022-12-18T00:23:41.975796+00:00
AIRFLOW_CTX_TRY_NUMBER=5
AIRFLOW_CTX_DAG_RUN_ID=manual__2022-12-18T00:23:41.975796+00:00
[2022-12-18T01:38:10.962+0000] {sql.py:253} INFO - Executing: 
            CREATE TABLE traffic_data(id INT NOT NULL, track_id INT NOT NULL, type VARCHAR(250) NOT NULL, traveled_d VARCHAR(250) NOT NULL, avg_speed VARCHAR(250) NOT NULL, lat VARCHAR(250) NOT NULL, lon VARCHAR(250) NOT NULL, speed VARCHAR(250) NOT NULL, lon_acc VARCHAR(250) NOT NULL, lat_acc VARCHAR(250) NOT NULL, time VARCHAR(250) NOT NULL);
        
[2022-12-18T01:38:12.854+0000] {base.py:73} INFO - Using connection ID 'dbt_setup' for task execution.
[2022-12-18T01:38:15.895+0000] {base.py:73} INFO - Using connection ID 'dbt_setup' for task execution.
[2022-12-18T01:38:15.912+0000] {sql.py:364} INFO - Running statement: 
            CREATE TABLE traffic_data(id INT NOT NULL, track_id INT NOT NULL, type VARCHAR(250) NOT NULL, traveled_d VARCHAR(250) NOT NULL, avg_speed VARCHAR(250) NOT NULL, lat VARCHAR(250) NOT NULL, lon VARCHAR(250) NOT NULL, speed VARCHAR(250) NOT NULL, lon_acc VARCHAR(250) NOT NULL, lat_acc VARCHAR(250) NOT NULL, time VARCHAR(250) NOT NULL);
        , parameters: None
[2022-12-18T01:38:15.926+0000] {taskinstance.py:1772} ERROR - Task failed with exception
Traceback (most recent call last):
  File "/home/airflow/.local/lib/python3.7/site-packages/airflow/providers/common/sql/operators/sql.py", line 261, in execute
    return_last=self.return_last,
  File "/home/airflow/.local/lib/python3.7/site-packages/airflow/providers/common/sql/hooks/sql.py", line 338, in run
    self._run_command(cur, sql_statement, parameters)
  File "/home/airflow/.local/lib/python3.7/site-packages/airflow/providers/common/sql/hooks/sql.py", line 369, in _run_command
    cur.execute(sql_statement)
psycopg2.errors.DuplicateTable: relation "traffic_data" already exists

[2022-12-18T01:38:15.966+0000] {taskinstance.py:1327} INFO - Marking task as FAILED. dag_id=postgres_with_***, task_id=create_table_task, execution_date=20221218T002341, start_date=20221218T013638, end_date=20221218T013815
[2022-12-18T01:38:16.079+0000] {standard_task_runner.py:105} ERROR - Failed to execute job 64 for task create_table_task (relation "traffic_data" already exists
; 1161)
[2022-12-18T01:38:16.163+0000] {local_task_job.py:159} INFO - Task exited with return code 1
[2022-12-18T01:38:16.314+0000] {taskinstance.py:2582} INFO - 0 downstream tasks scheduled from follow-on schedule check
