[2022-12-18T02:07:42.922+0000] {taskinstance.py:1087} INFO - Dependencies all met for <TaskInstance: postgres_with_airflow.create_table_task manual__2022-12-18T00:23:41.975796+00:00 [queued]>
[2022-12-18T02:07:42.966+0000] {taskinstance.py:1087} INFO - Dependencies all met for <TaskInstance: postgres_with_airflow.create_table_task manual__2022-12-18T00:23:41.975796+00:00 [queued]>
[2022-12-18T02:07:42.971+0000] {taskinstance.py:1283} INFO - 
--------------------------------------------------------------------------------
[2022-12-18T02:07:42.973+0000] {taskinstance.py:1284} INFO - Starting attempt 8 of 8
[2022-12-18T02:07:42.974+0000] {taskinstance.py:1285} INFO - 
--------------------------------------------------------------------------------
[2022-12-18T02:07:43.052+0000] {taskinstance.py:1304} INFO - Executing <Task(PostgresOperator): create_table_task> on 2022-12-18 00:23:41.975796+00:00
[2022-12-18T02:07:43.081+0000] {standard_task_runner.py:55} INFO - Started process 306 to run task
[2022-12-18T02:07:43.108+0000] {standard_task_runner.py:82} INFO - Running: ['***', 'tasks', 'run', 'postgres_with_***', 'create_table_task', 'manual__2022-12-18T00:23:41.975796+00:00', '--job-id', '68', '--raw', '--subdir', 'DAGS_FOLDER/dag_with_postgres.py', '--cfg-path', '/tmp/tmp_6zhh_vu']
[2022-12-18T02:07:43.111+0000] {standard_task_runner.py:83} INFO - Job 68: Subtask create_table_task
[2022-12-18T02:07:43.766+0000] {task_command.py:389} INFO - Running <TaskInstance: postgres_with_airflow.create_table_task manual__2022-12-18T00:23:41.975796+00:00 [running]> on host f376bb2680d1
[2022-12-18T02:08:17.524+0000] {taskinstance.py:1513} INFO - Exporting the following env vars:
AIRFLOW_CTX_DAG_OWNER=***
AIRFLOW_CTX_DAG_ID=postgres_with_***
AIRFLOW_CTX_TASK_ID=create_table_task
AIRFLOW_CTX_EXECUTION_DATE=2022-12-18T00:23:41.975796+00:00
AIRFLOW_CTX_TRY_NUMBER=8
AIRFLOW_CTX_DAG_RUN_ID=manual__2022-12-18T00:23:41.975796+00:00
[2022-12-18T02:08:17.539+0000] {sql.py:253} INFO - Executing: 
            CREATE TABLE traffic_data(id INT NOT NULL, track_id INT NOT NULL, type VARCHAR(250) NOT NULL, traveled_d VARCHAR(250) NOT NULL, avg_speed VARCHAR(250) NOT NULL, lat VARCHAR(250) NOT NULL, lon VARCHAR(250) NOT NULL, speed VARCHAR(250) NOT NULL, lon_acc VARCHAR(250) NOT NULL, lat_acc VARCHAR(250) NOT NULL, time VARCHAR(250) NOT NULL);
        
[2022-12-18T02:08:17.745+0000] {base.py:73} INFO - Using connection ID 'dbt_setup' for task execution.
[2022-12-18T02:08:36.486+0000] {base.py:73} INFO - Using connection ID 'dbt_setup' for task execution.
[2022-12-18T02:08:36.530+0000] {sql.py:364} INFO - Running statement: 
            CREATE TABLE traffic_data(id INT NOT NULL, track_id INT NOT NULL, type VARCHAR(250) NOT NULL, traveled_d VARCHAR(250) NOT NULL, avg_speed VARCHAR(250) NOT NULL, lat VARCHAR(250) NOT NULL, lon VARCHAR(250) NOT NULL, speed VARCHAR(250) NOT NULL, lon_acc VARCHAR(250) NOT NULL, lat_acc VARCHAR(250) NOT NULL, time VARCHAR(250) NOT NULL);
        , parameters: None
[2022-12-18T02:08:36.550+0000] {taskinstance.py:1772} ERROR - Task failed with exception
Traceback (most recent call last):
  File "/home/airflow/.local/lib/python3.7/site-packages/airflow/providers/common/sql/operators/sql.py", line 261, in execute
    return_last=self.return_last,
  File "/home/airflow/.local/lib/python3.7/site-packages/airflow/providers/common/sql/hooks/sql.py", line 338, in run
    self._run_command(cur, sql_statement, parameters)
  File "/home/airflow/.local/lib/python3.7/site-packages/airflow/providers/common/sql/hooks/sql.py", line 369, in _run_command
    cur.execute(sql_statement)
psycopg2.errors.DuplicateTable: relation "traffic_data" already exists

[2022-12-18T02:08:36.614+0000] {taskinstance.py:1327} INFO - Marking task as FAILED. dag_id=postgres_with_***, task_id=create_table_task, execution_date=20221218T002341, start_date=20221218T020742, end_date=20221218T020836
[2022-12-18T02:08:36.753+0000] {standard_task_runner.py:105} ERROR - Failed to execute job 68 for task create_table_task (relation "traffic_data" already exists
; 306)
[2022-12-18T02:08:36.818+0000] {local_task_job.py:159} INFO - Task exited with return code 1
[2022-12-18T02:08:36.949+0000] {taskinstance.py:2582} INFO - 0 downstream tasks scheduled from follow-on schedule check
