[2022-12-18T01:31:39.933+0000] {taskinstance.py:1087} INFO - Dependencies all met for <TaskInstance: postgres_with_airflow.create_table_task manual__2022-12-18T00:23:41.975796+00:00 [queued]>
[2022-12-18T01:31:39.973+0000] {taskinstance.py:1087} INFO - Dependencies all met for <TaskInstance: postgres_with_airflow.create_table_task manual__2022-12-18T00:23:41.975796+00:00 [queued]>
[2022-12-18T01:31:39.973+0000] {taskinstance.py:1283} INFO - 
--------------------------------------------------------------------------------
[2022-12-18T01:31:39.974+0000] {taskinstance.py:1284} INFO - Starting attempt 3 of 3
[2022-12-18T01:31:39.975+0000] {taskinstance.py:1285} INFO - 
--------------------------------------------------------------------------------
[2022-12-18T01:31:40.022+0000] {taskinstance.py:1304} INFO - Executing <Task(PostgresOperator): create_table_task> on 2022-12-18 00:23:41.975796+00:00
[2022-12-18T01:31:40.035+0000] {standard_task_runner.py:55} INFO - Started process 991 to run task
[2022-12-18T01:31:40.052+0000] {standard_task_runner.py:82} INFO - Running: ['***', 'tasks', 'run', 'postgres_with_***', 'create_table_task', 'manual__2022-12-18T00:23:41.975796+00:00', '--job-id', '62', '--raw', '--subdir', 'DAGS_FOLDER/dag_with_postgres.py', '--cfg-path', '/tmp/tmpj391evbe']
[2022-12-18T01:31:40.054+0000] {standard_task_runner.py:83} INFO - Job 62: Subtask create_table_task
[2022-12-18T01:31:40.229+0000] {task_command.py:389} INFO - Running <TaskInstance: postgres_with_airflow.create_table_task manual__2022-12-18T00:23:41.975796+00:00 [running]> on host f376bb2680d1
[2022-12-18T01:31:40.452+0000] {taskinstance.py:1513} INFO - Exporting the following env vars:
AIRFLOW_CTX_DAG_OWNER=***
AIRFLOW_CTX_DAG_ID=postgres_with_***
AIRFLOW_CTX_TASK_ID=create_table_task
AIRFLOW_CTX_EXECUTION_DATE=2022-12-18T00:23:41.975796+00:00
AIRFLOW_CTX_TRY_NUMBER=3
AIRFLOW_CTX_DAG_RUN_ID=manual__2022-12-18T00:23:41.975796+00:00
[2022-12-18T01:31:40.455+0000] {sql.py:253} INFO - Executing: 
            CREATE TABLE traffic_data(id INT NOT NULL, track_id INT NOT NULL, type VARCHAR(250) NOT NULL, traveled_d VARCHAR(250) NOT NULL, avg_speed VARCHAR(250) NOT NULL, lat VARCHAR(250) NOT NULL, lon VARCHAR(250) NOT NULL, speed VARCHAR(250) NOT NULL, lon_acc VARCHAR(250) NOT NULL, lat_acc VARCHAR(250) NOT NULL, time VARCHAR(250) NOT NULL);
        
[2022-12-18T01:31:40.478+0000] {base.py:73} INFO - Using connection ID 'dbt_setup' for task execution.
[2022-12-18T01:32:05.255+0000] {base_job.py:232} ERROR - LocalTaskJob heartbeat got an exception
Traceback (most recent call last):
  File "/home/airflow/.local/lib/python3.7/site-packages/sqlalchemy/engine/base.py", line 3361, in _wrap_pool_connect
    return fn()
  File "/home/airflow/.local/lib/python3.7/site-packages/sqlalchemy/pool/base.py", line 325, in connect
    return _ConnectionFairy._checkout(self)
  File "/home/airflow/.local/lib/python3.7/site-packages/sqlalchemy/pool/base.py", line 888, in _checkout
    fairy = _ConnectionRecord.checkout(pool)
  File "/home/airflow/.local/lib/python3.7/site-packages/sqlalchemy/pool/base.py", line 491, in checkout
    rec = pool._do_get()
  File "/home/airflow/.local/lib/python3.7/site-packages/sqlalchemy/pool/impl.py", line 256, in _do_get
    return self._create_connection()
  File "/home/airflow/.local/lib/python3.7/site-packages/sqlalchemy/pool/base.py", line 271, in _create_connection
    return _ConnectionRecord(self)
  File "/home/airflow/.local/lib/python3.7/site-packages/sqlalchemy/pool/base.py", line 386, in __init__
    self.__connect()
  File "/home/airflow/.local/lib/python3.7/site-packages/sqlalchemy/pool/base.py", line 685, in __connect
    pool.logger.debug("Error on connect(): %s", e)
  File "/home/airflow/.local/lib/python3.7/site-packages/sqlalchemy/util/langhelpers.py", line 72, in __exit__
    with_traceback=exc_tb,
  File "/home/airflow/.local/lib/python3.7/site-packages/sqlalchemy/util/compat.py", line 210, in raise_
    raise exception
  File "/home/airflow/.local/lib/python3.7/site-packages/sqlalchemy/pool/base.py", line 680, in __connect
    self.dbapi_connection = connection = pool._invoke_creator(self)
  File "/home/airflow/.local/lib/python3.7/site-packages/sqlalchemy/engine/create.py", line 578, in connect
    return dialect.connect(*cargs, **cparams)
  File "/home/airflow/.local/lib/python3.7/site-packages/sqlalchemy/engine/default.py", line 598, in connect
    return self.dbapi.connect(*cargs, **cparams)
  File "/home/airflow/.local/lib/python3.7/site-packages/psycopg2/__init__.py", line 122, in connect
    conn = _connect(dsn, connection_factory=connection_factory, **kwasync)
psycopg2.OperationalError: could not translate host name "postgres" to address: Temporary failure in name resolution


The above exception was the direct cause of the following exception:

Traceback (most recent call last):
  File "/home/airflow/.local/lib/python3.7/site-packages/airflow/jobs/base_job.py", line 204, in heartbeat
    session.merge(self)
  File "/home/airflow/.local/lib/python3.7/site-packages/sqlalchemy/orm/session.py", line 3057, in merge
    _resolve_conflict_map=_resolve_conflict_map,
  File "/home/airflow/.local/lib/python3.7/site-packages/sqlalchemy/orm/session.py", line 3135, in _merge
    options=options,
  File "/home/airflow/.local/lib/python3.7/site-packages/sqlalchemy/orm/session.py", line 2856, in get
    execution_options=execution_options,
  File "/home/airflow/.local/lib/python3.7/site-packages/sqlalchemy/orm/session.py", line 2974, in _get_impl
    load_options=load_options,
  File "/home/airflow/.local/lib/python3.7/site-packages/sqlalchemy/orm/loading.py", line 534, in load_on_pk_identity
    bind_arguments=bind_arguments,
  File "/home/airflow/.local/lib/python3.7/site-packages/sqlalchemy/orm/session.py", line 1713, in execute
    conn = self._connection_for_bind(bind)
  File "/home/airflow/.local/lib/python3.7/site-packages/sqlalchemy/orm/session.py", line 1553, in _connection_for_bind
    engine, execution_options
  File "/home/airflow/.local/lib/python3.7/site-packages/sqlalchemy/orm/session.py", line 747, in _connection_for_bind
    conn = bind.connect()
  File "/home/airflow/.local/lib/python3.7/site-packages/sqlalchemy/engine/base.py", line 3315, in connect
    return self._connection_cls(self, close_with_result=close_with_result)
  File "/home/airflow/.local/lib/python3.7/site-packages/sqlalchemy/engine/base.py", line 96, in __init__
    else engine.raw_connection()
  File "/home/airflow/.local/lib/python3.7/site-packages/sqlalchemy/engine/base.py", line 3394, in raw_connection
    return self._wrap_pool_connect(self.pool.connect, _connection)
  File "/home/airflow/.local/lib/python3.7/site-packages/sqlalchemy/engine/base.py", line 3365, in _wrap_pool_connect
    e, dialect, self
  File "/home/airflow/.local/lib/python3.7/site-packages/sqlalchemy/engine/base.py", line 2199, in _handle_dbapi_exception_noconnection
    sqlalchemy_exception, with_traceback=exc_info[2], from_=e
  File "/home/airflow/.local/lib/python3.7/site-packages/sqlalchemy/util/compat.py", line 210, in raise_
    raise exception
  File "/home/airflow/.local/lib/python3.7/site-packages/sqlalchemy/engine/base.py", line 3361, in _wrap_pool_connect
    return fn()
  File "/home/airflow/.local/lib/python3.7/site-packages/sqlalchemy/pool/base.py", line 325, in connect
    return _ConnectionFairy._checkout(self)
  File "/home/airflow/.local/lib/python3.7/site-packages/sqlalchemy/pool/base.py", line 888, in _checkout
    fairy = _ConnectionRecord.checkout(pool)
  File "/home/airflow/.local/lib/python3.7/site-packages/sqlalchemy/pool/base.py", line 491, in checkout
    rec = pool._do_get()
  File "/home/airflow/.local/lib/python3.7/site-packages/sqlalchemy/pool/impl.py", line 256, in _do_get
    return self._create_connection()
  File "/home/airflow/.local/lib/python3.7/site-packages/sqlalchemy/pool/base.py", line 271, in _create_connection
    return _ConnectionRecord(self)
  File "/home/airflow/.local/lib/python3.7/site-packages/sqlalchemy/pool/base.py", line 386, in __init__
    self.__connect()
  File "/home/airflow/.local/lib/python3.7/site-packages/sqlalchemy/pool/base.py", line 685, in __connect
    pool.logger.debug("Error on connect(): %s", e)
  File "/home/airflow/.local/lib/python3.7/site-packages/sqlalchemy/util/langhelpers.py", line 72, in __exit__
    with_traceback=exc_tb,
  File "/home/airflow/.local/lib/python3.7/site-packages/sqlalchemy/util/compat.py", line 210, in raise_
    raise exception
  File "/home/airflow/.local/lib/python3.7/site-packages/sqlalchemy/pool/base.py", line 680, in __connect
    self.dbapi_connection = connection = pool._invoke_creator(self)
  File "/home/airflow/.local/lib/python3.7/site-packages/sqlalchemy/engine/create.py", line 578, in connect
    return dialect.connect(*cargs, **cparams)
  File "/home/airflow/.local/lib/python3.7/site-packages/sqlalchemy/engine/default.py", line 598, in connect
    return self.dbapi.connect(*cargs, **cparams)
  File "/home/airflow/.local/lib/python3.7/site-packages/psycopg2/__init__.py", line 122, in connect
    conn = _connect(dsn, connection_factory=connection_factory, **kwasync)
sqlalchemy.exc.OperationalError: (psycopg2.OperationalError) could not translate host name "postgres" to address: Temporary failure in name resolution

(Background on this error at: https://sqlalche.me/e/14/e3q8)
[2022-12-18T01:32:05.858+0000] {base.py:73} INFO - Using connection ID 'dbt_setup' for task execution.
[2022-12-18T01:32:05.902+0000] {sql.py:364} INFO - Running statement: 
            CREATE TABLE traffic_data(id INT NOT NULL, track_id INT NOT NULL, type VARCHAR(250) NOT NULL, traveled_d VARCHAR(250) NOT NULL, avg_speed VARCHAR(250) NOT NULL, lat VARCHAR(250) NOT NULL, lon VARCHAR(250) NOT NULL, speed VARCHAR(250) NOT NULL, lon_acc VARCHAR(250) NOT NULL, lat_acc VARCHAR(250) NOT NULL, time VARCHAR(250) NOT NULL);
        , parameters: None
[2022-12-18T01:32:05.936+0000] {taskinstance.py:1772} ERROR - Task failed with exception
Traceback (most recent call last):
  File "/home/airflow/.local/lib/python3.7/site-packages/airflow/providers/common/sql/operators/sql.py", line 261, in execute
    return_last=self.return_last,
  File "/home/airflow/.local/lib/python3.7/site-packages/airflow/providers/common/sql/hooks/sql.py", line 338, in run
    self._run_command(cur, sql_statement, parameters)
  File "/home/airflow/.local/lib/python3.7/site-packages/airflow/providers/common/sql/hooks/sql.py", line 369, in _run_command
    cur.execute(sql_statement)
psycopg2.errors.DuplicateTable: relation "traffic_data" already exists

[2022-12-18T01:32:06.178+0000] {taskinstance.py:1327} INFO - Marking task as FAILED. dag_id=postgres_with_***, task_id=create_table_task, execution_date=20221218T002341, start_date=20221218T013139, end_date=20221218T013206
[2022-12-18T01:32:06.276+0000] {standard_task_runner.py:105} ERROR - Failed to execute job 62 for task create_table_task (relation "traffic_data" already exists
; 991)
[2022-12-18T01:32:06.342+0000] {local_task_job.py:159} INFO - Task exited with return code 1
[2022-12-18T01:32:06.499+0000] {taskinstance.py:2582} INFO - 0 downstream tasks scheduled from follow-on schedule check
